<?xml version="1.0"?>
<robot name="racecar" xmlns:xacro="http://www.ros.org/wiki/xacro">

  <xacro:include filename="$(find racecar_description)/urdf/macros.xacro" />

  <!-- Add chassis and it's inertia link -->

  <link name="base_link" />

  <link name="chassis">
    <visual>
      <xacro:chassis_geometry/>
      <material name="blue" />
    </visual>
  </link>

  <joint name="base_link_joint" type="fixed">
    <origin xyz="0 0 0.05" rpy="0 0 0" />
    <parent link="base_link" />
    <child link="chassis" />
  </joint>

  <link name="chassis_inertia">
    <inertial>
      <xacro:chassis_inertial_params />
    </inertial>
  </link>

  <joint name="chassis_inertia_joint" type="fixed">
    <origin xyz="0 0 0" rpy="0 0 0" />
    <parent link="chassis" />
    <child link="chassis_inertia" />
  </joint>

  <!-- Add the left rear wheel with its joints and tranmissions -->

  <link name="left_rear_wheel">
    <inertial>
      <xacro:left_wheels_inertial_params />
    </inertial>
    <visual>
      <xacro:left_rear_wheel_geometry />
      <material name="black" />
    </visual>
    <collision>robot
      <xacro:left_wheels_collision_geometry />
    </collision>
  </link>

  <joint name="left_rear_wheel_joint" type="continuous">
    <origin xyz="0 0.1 0" rpy="1.5708 0 0" />
    <parent link="chassis" />
    <child link="left_rear_wheel" />
    <axis xyz="0 0 -1" />
    <limit effort="10" velocity="100" />
  </joint>

  <xacro:wheel_transmission name="left_rear_wheel" />

  <!-- Add the right rear wheel with its joints and tranmissions -->

  <link name="right_rear_wheel">
    <inertial>
      <xacro:right_wheels_inertial_params />
    </inertial>
    <visual>
      <xacro:right_rear_wheel_geometry />
      <material name="black" />
    </visual>
    <collision>
      <xacro:right_wheels_collision_geometry />
    </collision>
  </link>

  <joint name="right_rear_wheel_joint" type="continuous">
    <origin xyz="0 -0.1 0" rpy="1.5708 0 0" />
    <parent link="chassis" />
    <child link="right_rear_wheel" />
    <axis xyz="0 0 -1" />
    <limit effort="10" velocity="100" />
  </joint>

  <xacro:wheel_transmission name="right_rear_wheel" />

  <!-- Add the left steering hinge with its joints and tranmissions -->

  <link name="left_steering_hinge">
    <inertial>
      <xacro:steering_hinge_inertial_params />
    </inertial>
    <visual>
      <xacro:left_steering_hinge_geometry />
      <material name="grey" />
    </visual>
  </link>

  <joint name="left_steering_hinge_joint" type="revolute">
    <origin xyz="0.325 0.1 0" rpy="0 1.5708 0" />
    <parent link="chassis" />
    <child link="left_steering_hinge" />
    <axis xyz="-1 0 0" />
    <limit lower="-1.0" upper="1.0" effort="10" velocity="100" />
  </joint>

  <xacro:steering_hinge_transmission name="left_steering_hinge" />

  <!-- Add the right steering hinge with its joints and tranmissions -->

  <link name="right_steering_hinge">
    <inertial>
      <xacro:steering_hinge_inertial_params />
    </inertial>
    <visual>
      <xacro:right_steering_hinge_geometry />
      <material name="grey" />
    </visual>
  </link>

  <joint name="right_steering_hinge_joint" type="continuous">
    <origin xyz="0.325 -0.1 0" rpy="0 1.5708 0" />
    <parent link="chassis" />
    <child link="right_steering_hinge" />
    <axis xyz="-1 0 0" />
    <limit lower="-1.0" upper="1.0" effort="10" velocity="100" />
  </joint>

  <xacro:steering_hinge_transmission name="right_steering_hinge" />

  <!-- Add the left front wheel with its joints and tranmissions -->

  <link name="left_front_wheel">
    <inertial>
      <xacro:left_wheels_inertial_params />
    </inertial>
    <visual>
      <xacro:left_front_wheel_geometry />
      <material name="black" />
    </visual>
    <collision>
      <xacro:left_wheels_collision_geometry />
    </collision>
  </link>

  <joint name="left_front_wheel_joint" type="continuous">
    <origin xyz="0 0 0" rpy="1.5708 0 0" />
    <parent link="left_steering_hinge" />
    <child link="left_front_wheel" />
    <axis xyz="0 0 -1" />
    <limit effort="10" velocity="100" />
  </joint>

  <xacro:wheel_transmission name="left_front_wheel" />

  <!-- Add the left front wheel with its joints and tranmissions -->

  <link name="right_front_wheel">
    <inertial>
      <xacro:right_wheels_inertial_params />
    </inertial>
    <visual>
      <xacro:right_front_wheel_geometry />
      <material name="black" />
    </visual>
    <collision>
      <xacro:right_wheels_collision_geometry />
    </collision>
  </link>

  <joint name="right_front_wheel_joint" type="continuous">
    <origin xyz="0 0 0" rpy="1.5708 0 0" />
    <parent link="right_steering_hinge" />
    <child link="right_front_wheel" />
    <axis xyz="0 0 -1" />
    <limit effort="10" velocity="100"/>
  </joint>
  
  <xacro:wheel_transmission name="right_front_wheel" />

    <!-- realsense link -->
    <link name="rs200_camera">
        <visual>
            <origin rpy="0 0 0" xyz="0 0 0"/>
            <geometry>
                <mesh filename="package://realsense_gazebo_plugin/models/realsense_camera/meshes/realsense.dae"/>
            </geometry>
        </visual>
        <collision>
            <geometry>
                <box size="0.0078 0.130 0.0192"/>
            </geometry>
        </collision>
        <inertial>
            <mass value="0.0615752"/>
            <origin rpy="0 0 0" xyz="0 0 0"/>
            <inertia ixx="9.108e-05"
                     ixy="0"
                     ixz="0"
                     iyy="2.51e-06"
                     iyz="0"
                     izz="8.931e-05"
            />
        </inertial>
    </link>

    <!-- Virtual links representing the cameras positons and orientations-->
    <link name="color" />
    <link name="depth" />
    <link name="ired1" />
    <link name="ired2" />

    <!-- Joints positioning the virtual links with respect to the camera main link-->
    <joint name="color_joint" type="fixed">
        <parent link="rs200_camera" />
        <child link="color" />
        <!-- <origin xyz="0 -0.046 0.004" rpy="0 0 0"/> -->
        <!-- The default position is change since in Rviz the cloud depth axis is Z not X-->
        <origin xyz="0 -0.046 0.004" rpy="${pi/2} ${pi} ${pi/2}"/>
    </joint>

    <joint name="depth_joint" type="fixed">
        <parent link="rs200_camera" />
        <child link="depth" />
        <origin xyz="0 -0.03 0.004" rpy="0 0 0"/>
    </joint>

    <joint name="ired1_joint" type="fixed">
        <parent link="rs200_camera" />
        <child link="ired1" />
        <origin xyz="0 -0.06 0.004" rpy="0 0 0"/>
    </joint>

    <joint name="ired2_joint" type="fixed">
        <parent link="rs200_camera" />
        <child link="ired2" />
        <origin xyz="0 0.01 0.004" rpy="0 0 0"/>
    </joint>

<joint name="rs200_camera_joint" type="fixed">
    <origin xyz="0.37 0 0.02" rpy="0 0 0" />
    <parent link="chassis" />
    <child link="rs200_camera" />
  </joint>
  
      
  <gazebo>
    <plugin name="gazebo_ros_control" filename="libgazebo_ros_control.so">
    <robotNamespace>/racecar</robotNamespace>
    <!-- <robotSimType>gazebo_ros_control/DefaultRobotHWSim</robotSimType> -->
    </plugin>
  </gazebo>
  
<!-- **********************************************************-->
<!-- GAZEBO DEFINITIONS ***************************************-->

    <!-- Load plugin to the model ("robot" in urdf format)-->
    <gazebo>
        <plugin name="realsense_plugin" filename="librealsense_gazebo_plugin.so"/>
        <!--<pose frame="">0 0 0.015 0 0 0</pose>-->
    </gazebo>

    <!-- Load parameters to model's main link-->
    <gazebo reference="rs200_camera">
        <self_collide>0</self_collide>
        <enable_wind>0</enable_wind>
        <kinematic>0</kinematic>
        <gravity>1</gravity>
        <!--<mu>1</mu>-->
        <mu2>1</mu2>
        <fdir1>0 0 0</fdir1>
        <!--<slip1>0</slip1>
        <slip2>0</slip2>-->
        <kp>1e+13</kp>
        <kd>1</kd>
        <!--<max_vel>0.01</max_vel>
        <min_depth>0</min_depth>-->

        <sensor name="color" type="camera">
            <pose frame="">0 -0.046 0.004 0 0 0</pose>
            <camera name="__default__">
            <horizontal_fov>1.047</horizontal_fov>
            <image>
                <width>640</width>
                <height>480</height>
                <format>RGB_INT8</format>
            </image>
            <clip>
                <near>0.1</near>
                <far>100</far>
            </clip>
            <noise>
                <type>gaussian</type>
                <mean>0.0</mean>
                <stddev>0.007</stddev>
            </noise>
            </camera>
            <always_on>1</always_on>
            <update_rate>60</update_rate>
            <visualize>1</visualize>
        </sensor>
        <sensor name="ired1" type="camera">
            <pose frame="">0 -0.06 0.004 0 0 0</pose>
            <camera name="__default__">
            <horizontal_fov>1.047</horizontal_fov>
            <image>
                <width>640</width>
                <height>480</height>
                <format>L_INT8</format>
            </image>
            <clip>
                <near>0.1</near>
                <far>100</far>
            </clip>
            <noise>
                <type>gaussian</type>
                <mean>0.0</mean>
                <stddev>0.05</stddev>
            </noise>
            </camera>
            <always_on>1</always_on>
            <update_rate>60</update_rate>
            <visualize>0</visualize>
        </sensor>
        <sensor name="ired2" type="camera">
            <pose frame="">0 0.01 0.004 0 0 0</pose>
            <camera name="__default__">
            <horizontal_fov>1.047</horizontal_fov>
            <image>
                <width>640</width>
                <height>480</height>
                <format>L_INT8</format>
            </image>
            <clip>
                <near>0.1</near>
                <far>100</far>
            </clip>
            <noise>
                <type>gaussian</type>
                <mean>0.0</mean>
                <stddev>0.05</stddev>
            </noise>
            </camera>
            <always_on>1</always_on>
            <update_rate>60</update_rate>
            <visualize>0</visualize>
        </sensor>
        <sensor name="depth" type="depth">
            <pose frame="">0 -0.03 0.004 0 0 0</pose>
            <camera name="__default__">
            <horizontal_fov>1.047</horizontal_fov>
            <image>
                    <width>640</width>
                    <height>480</height>
            </image>
            <clip>
                    <near>0.1</near>
                    <far>100</far>
            </clip>
            <noise>
                    <type>gaussian</type>
                    <mean>0.0</mean>
                    <stddev>0.100</stddev>
            </noise>
            </camera>
            <always_on>1</always_on>
            <update_rate>60</update_rate>
            <visualize>0</visualize>
        </sensor>
    </gazebo>


  <!-- Add the remaining xacros -->

  <xacro:include filename="$(find racecar_description)/urdf/racecar_realsense.gazebo" />
  <xacro:include filename="$(find racecar_description)/urdf/materials.xacro" />

</robot>
